Workbook

Sheet Leads
A1: First Name | B1: Last Name | C1: Position | D1: Company | E1: Company Size | F1: Industry | G1: Location | H1: Website | I1: LinkedIn URL | J1: Company LinkedIn | K1: Headline | L1: Position Dates | M1: Email | N1: Phone | O1: Intent Type | P1: Intent | Q1: Intent Keyword | R1: ICP Fit Score | S1: Intent Score | T1: Total Score | U1: Score Reasoning | V1: Open To Work | W1: Created (PHT) | X1: Export Status | Y1: Gojiberry Contact ID
A2: Riley | B2: Hennigh 🏴 | C2: Founder & Creative Director | D2: Oratory | E2: Myself Only | F2: Design Services | G2: Oklahoma City, Oklahoma, United States | H2: http://riley.cx | I2: https://www.linkedin.com/in/rileyhennigh | J2: https://linkedin.com/company/99470125 | K2: I help B2B software startups look and feel like established players. | L2: 02/01/2024 - Present | O2: RECENT_ACTIVITY | P2: Top 5% most active in your ICP (LinkedIn) | R2: 0.86 | S2: 1.2 | T2: 1.9 | U2: Founder aligns with ICP; Design Services in US; size slightly smaller but adjacent. | V2: No | W2: 2026-09-07 09:25 | X2: NEW - not yet exported | Y2: 17429758
A3: Laura | B3: Wachowiak (Antolak) | C3: Creative Director | D3: LJ Marketing & Media | E3: 1-10 employees | F3: Marketing Services | G3: San Diego, California, United States | I3: https://www.linkedin.com/in/laurawachowiak | J3: https://www.linkedin.com/company/lj-marketing-media | K3: Creative Operations & Marketing Leader | Brand, Content & Campaign Execution | Workflow Systems, Internal Communications & Team Delivery | L3: January 2025 - Present | O3: RECENT_ACTIVITY | P3: Top 5% most active in your ICP (LinkedIn) | R3: 0.96 | S3: 1.2 | T3: 2 | U3: Role, industry, and location align with the ICP; company size is one band smaller than the ICP. | V3: No | W3: 2026-09-07 09:25 | X3: NEW - not yet exported | Y3: 17429737
A4: Chloe | B4: Akahori | C4: Creative Director | D4: Domino New York | E4: 2-10 | F4: Design Services | G4: New York, New York, United States | H4: dominony.com | I4: https://www.linkedin.com/in/chloeakahori | J4: https://www.linkedin.com/company/dominonewyork | K4: Creative Director | L4: January 2019 - Present | O4: RECENT_ACTIVITY | P4: Top 5% most active in your ICP (LinkedIn) | R4: 0.98 | S4: 1.2 | T4: 2.1 | U4: Role and company fit ICP; location and industry align; strong all-around match. | V4: No | W4: 2026-09-07 09:25 | X4: NEW - not yet exported | Y4: 17429708
A5: Brendon | B5: McLean | C5: Owner | Creative Director | D5: Latitude Studios | E5: 1-10 employees | F5: Marketing Services | G5: Parkville, Maryland, United States | H5: http://www.latitudestudios.com | I5: https://www.linkedin.com/in/brendonmclean | J5: https://www.linkedin.com/company/latitude-studios | K5: Creative Director at Latitude Studios | L5: May 2007 - Present | O5: RECENT_ACTIVITY | P5: Top 5% most active in your ICP (LinkedIn) | R5: 0.89 | S5: 1.2 | T5: 1.9 | U5: Role aligns with ICP; US location; industry match; company size slightly smaller. | V5: No | W5: 2026-09-07 09:25 | X5: NEW - not yet exported | Y5: 17429704
A6: Kristin | B6: Wellmer | C6: Creative Director | D6: Crybaby Kingdom | E6: 1-10 employees | F6: Marketing Services | G6: Los Angeles, California, United States | H6: https://www.linkedin.com/redir/redirect?url=https://wellmer.co/&urlhash=Th50&trk=public_profile_topcard-website | I6: https://www.linkedin.com/in/wwwellmer | J6: https://www.linkedin.com/company/crybaby-kingdom | K6: Co-Founder @ Crybaby Kingdom / Executive Creative Director / Director / Writer | L6: May 2024 - Present | O6: RECENT_ACTIVITY | P6: Top 5% most active in your ICP (LinkedIn) | R6: 0.85 | S6: 1.2 | T6: 1.9 | U6: Creative Director in Marketing Services from US with near-fit company size aligns with ICP. | V6: No | W6: 2026-09-07 09:25 | X6: NEW - not yet exported | Y6: 17429699
A7: Kristine | B7: Jacobson | C7: Founder, CEO | D7: Conveyance Marketing Group | E7: 11-50 employees | F7: Marketing Services | G7: Leesburg, Virginia, United States | H7: http://www.conveyancemarketinggroup.com | I7: https://www.linkedin.com/in/kristinejacobsoncmo | J7: https://www.linkedin.com/company/conveyance-marketing-group | K7: Founder and CEO, Conveyance Marketing Group | L7: March 2009 - Present | O7: RECENT_ACTIVITY | P7: Top 5% most active in your ICP (LinkedIn) | R7: 0.96 | S7: 1.2 | T7: 2 | U7: Role aligns with ICP and location/industry/size match precisely. | V7: No | W7: 2026-09-07 09:24 | X7: NEW - not yet exported | Y7: 17429673
A8: Sulman | B8: Mirza | C8: Founder + Creative Director | D8: Resonant Design | E8: 2 - 10 | F8: Design Services | G8: Houston, Texas, United States | H8: https://resonant.work | I8: https://www.linkedin.com/in/sulmirza | J8: https://www.linkedin.com/company/resonant-studio/ | K8: Founder + Creative Director @ Resonant Design | Brand & Web | L8: 5/4/2025 - now | O8: RECENT_ACTIVITY | P8: Top 5% most active in your ICP (LinkedIn) | R8: 0.95 | S8: 1.2 | T8: 2 | U8: Role matches ICP; industry/location align; company size within allowed band. | V8: No | W8: 2026-09-07 09:24 | X8: NEW - not yet exported | Y8: 17429669
A9: Chad | B9: McCown | C9: Creative Director | D9: McCown Design Agency | E9: 1-10 employees | F9: Design Services | G9: Palos Verdes Peninsula, California, United States | H9: https://www.linkedin.com/redir/redirect?url=http://www.mccowndesignagency.com&urlhash=thwY&trk=public_profile_website | I9: https://www.linkedin.com/in/chadmccown | J9: https://www.linkedin.com/company/mccown-design-agency | K9: Creative Director @ McCown Design Agency • Illustration Representation @ Lemonade Illustration Agency | L9: 2005 - Present | O9: RECENT_ACTIVITY | P9: Top 5% most active in your ICP (LinkedIn) | R9: 0.83 | S9: 1.2 | T9: 1.8 | U9: Role matches ICP titles with seniority; location and industry align; company size slightly smaller than ICP but overall fit | V9: No | W9: 2026-09-07 09:24 | X9: NEW - not yet exported | Y9: 17429663
A10: Tierney | B10: Cunningham | C10: Creative Director | D10: Supermoon.us | E10: 1-10 employees | F10: Design Services | G10: Seattle, Washington, United States | H10: http://studiotierney.com | I10: https://www.linkedin.com/in/tierneycunningham | J10: https://linkedin.com/company/53174631 | K10: Brand Creative Director | L10: 08/01/2025 - Present | O10: RECENT_ACTIVITY | P10: Top 5% most active in your ICP (LinkedIn) | R10: 0.88 | S10: 1.2 | T10: 1.9 | U10: Creative Director aligns with ICP title; Design Services in US; company size close to ICP; location matches. | V10: No | W10: 2026-09-07 09:24 | X10: NEW - not yet exported | Y10: 17429637
A11: Noall-Scott | B11: Reid | C11: Founder / Creative Director | D11: Noall Scott | E11: 1-10 employees | F11: Marketing Services | G11: Greater Cleveland | H11: https://www.noallscott.com | I11: https://www.linkedin.com/in/noallreid | J11: https://www.linkedin.com/company/noall-scott | K11: Executive Creative Director | Creative Operations & Integrated Production Leader / Mountain Biking Enthusiast | L11: March 2008 - Present | O11: RECENT_ACTIVITY | P11: Top 5% most active in your ICP (LinkedIn) | R11: 0.92 | S11: 1.2 | T11: 2 | U11: Founder/Creative Director aligns with ICP; industry matches Marketing Services in US; location fits; size is just below ICP range. | V11: No | W11: 2026-09-07 09:24 | X11: NEW - not yet exported | Y11: 17429631
A12: Maria | B12: De La Cruz | C12: Founder / Creative Director | D12: Artropoliz | E12: Myself Only | F12: Design Services | G12: Redwood City, California, United States | H12: Artropoliz.com | I12: https://www.linkedin.com/in/maria-de-la-cruz-artropoliz | J12: https://www.linkedin.com/company/artropoliz | K12: Multidisciplinary Visual Designer | Illustrator | Founder, Artropoliz™ | Brand & Visual Storytelling | L12: March 2026 - Present | O12: RECENT_ACTIVITY | P12: Top 5% most active in your ICP (LinkedIn) | R12: 0.8 | S12: 1.2 | T12: 1.8 | U12: Role and location align with ICP; industry matches; company size does not. | V12: No | W12: 2026-09-07 09:24 | X12: NEW - not yet exported | Y12: 17429623
A13: Karine | B13: Makartichan | C13: Creative Director | D13: US Illustrations | E13: 11-50 employees | F13: Design Services | G13: Greater Boston | I13: https://www.linkedin.com/in/karine-makartichan | J13: https://www.linkedin.com/company/usillustrations | K13: Creative Director @US Illustrations | ABD Fine Arts, Character Design | L13: June 2017 - Present | O13: RECENT_ACTIVITY | P13: Top 5% most active in your ICP (LinkedIn) | R13: 0.96 | S13: 1.2 | T13: 2 | U13: Creative Director aligns with ICP roles and the company/region fit US marketing/design services. | V13: No | W13: 2026-09-07 09:24 | X13: NEW - not yet exported | Y13: 17429603
A14: Austin | B14: Robinson | C14: Founder, Head of Creative | D14: Absorb Studios | E14: 2 - 10 | F14: Advertising Services | G14: Greater Indianapolis | H14: www.Austin-Robinson.com | I14: https://www.linkedin.com/in/austin-robinson-b1b53a157 | J14: https://www.linkedin.com/company/absorbstudios | K14: Founder & Head of Creative, Cinematographer at Absorb Studios | L14: December 2022 - Present | O14: RECENT_ACTIVITY | P14: Top 5% most active in your ICP (LinkedIn) | R14: 0.92 | S14: 1.2 | T14: 2 | U14: Role aligns with ICP; industry/location/size match US Advertising Services. | V14: No | W14: 2026-09-07 09:24 | X14: NEW - not yet exported | Y14: 17429573
A15: Brooke | B15: White | C15: Client Success Manager | D15: Moonlight Digital | E15: 2-10 | F15: Marketing Services | G15: Highland, Michigan, United States | I15: https://www.linkedin.com/in/brooke-white-b5b763264 | J15: https://www.linkedin.com/company/moonlight-digital | K15: Client Success Manager | L15: May 2025 - Present | O15: RECENT_ACTIVITY | P15: Top 5% most active in your ICP (LinkedIn) | R15: 1 | S15: 1.2 | T15: 2.1 | U15: Role aligns with ICP titles; industry, location, and company size match the ICP criteria. | V15: No | W15: 2026-09-07 09:24 | X15: NEW - not yet exported | Y15: 17429569
A16: Nathan | B16: Orensten | C16: Creative Director | D16: READY SET NO | E16: 1-10 employees | F16: Marketing Services | G16: Columbus, Ohio, United States | I16: https://www.linkedin.com/in/nathan-orensten | J16: https://www.linkedin.com/company/ready-set-no | K16: Creative Director | L16: May 2025 - Present | O16: RECENT_ACTIVITY | P16: Top 5% most active in your ICP (LinkedIn) | R16: 1 | S16: 1.2 | T16: 2.1 | U16: Role, industry, location and size align with ICP. | V16: No | W16: 2026-09-07 09:24 | X16: NEW - not yet exported | Y16: 17429566
A17: Madi | B17: Balman | C17: Founder & Creative Director | D17: Skellydog | E17: 1-10 employees | F17: Marketing Services | G17: Norwich, Connecticut, United States | H17: www.skellydog.com | I17: https://www.linkedin.com/in/mnbalman | J17: https://www.linkedin.com/company/skellydog | K17: Brand Strategist & Creative Director | Fierce Advocate for Growing Bold, Strategy-Driven Brands | L17: 01/01/2016 - Present | O17: RECENT_ACTIVITY | P17: Top 5% most active in your ICP (LinkedIn) | R17: 0.94 | S17: 1.2 | T17: 2 | U17: Founder's role aligns with ICP; industry and location match US marketing services; company size slightly smaller but adjacent. | V17: No | W17: 2026-09-07 09:24 | X17: NEW - not yet exported | Y17: 17429515
A18: Ralph | B18: Renna | C18: Client Success Manager | D18: HeavySet Tech | E18: 1-10 employees | F18: Marketing Services | G18: Dallas-Fort Worth Metroplex | I18: https://www.linkedin.com/in/ralph-renna | J18: https://www.linkedin.com/company/heavy-set-tech | K18: Client Success Manager | AI-Powered Lead Acquisition & 24/7 Automated Scheduling to Scale Businesses. Focused on Contractor Growth Strategies and Lead Optimization. | L18: May 2026 - Present | O18: RECENT_ACTIVITY | P18: Top 5% most active in your ICP (LinkedIn) | R18: 0.9 | S18: 1.2 | T18: 2 | U18: Role matches ICP, location/industry align, company size close to ICP; scoring reflects near-fit with a modest size delta. | V18: No | W18: 2026-09-07 09:24 | X18: NEW - not yet exported | Y18: 17429514
A19: Michael | B19: Terranova | C19: Creative Director | D19: Fletcher Knight | E19: 11-50 employees | F19: Marketing Services | G19: New York City Metropolitan Area | H19: http://www.fletcherknight.com | I19: https://www.linkedin.com/in/michael-terranova-61321a29 | J19: https://www.linkedin.com/company/fletcherknight | K19: Creative Director at Fletcher Knight | L19: January 2014 - Present | O19: RECENT_ACTIVITY | P19: Top 5% most active in your ICP (LinkedIn) | R19: 0.97 | S19: 1.2 | T19: 2 | U19: Role and company fit ICP: Creative Director in Marketing Services, US. | V19: No | W19: 2026-09-07 09:24 | X19: NEW - not yet exported | Y19: 17429511
A20: Molly | B20: Durchholz | C20: Co-Founder & Creative Director | D20: Common Thread | E20: 1-10 employees | F20: Design Services | G20: Evansville, Indiana, United States | H20: mjdursigns.myportfolio.com | I20: https://www.linkedin.com/in/molly-durchholz-983403244 | J20: https://www.linkedin.com/company/ownyourthread | K20: Co-Founder & Creative Director | Common Thread Co. | L20: January 2026 - Present | O20: RECENT_ACTIVITY | P20: Top 5% most active in your ICP (LinkedIn) | R20: 0.87 | S20: 1.2 | T20: 1.9 | U20: Role maps to ICP titles; location is US and industry aligns; company size is one band below ICP. | V20: No | W20: 2026-09-07 09:24 | X20: NEW - not yet exported | Y20: 17429502
A21: Timothy | B21: Miley | C21: Founder / Head of Creative | D21: Miley Studios | E21: 2-10 | F21: Advertising Services | G21: Greater Reno Area, United States | H21: https://mileystudios.com | I21: https://www.linkedin.com/in/timmiley | J21: https://www.linkedin.com/company/miley-studios/ | K21: Founder, Miley Studios | Ad Person of the Year | Brand Strategy & Digital Marketing | 400+ Awards incl. Webby | L21: 1/01/2023 - now | O21: RECENT_ACTIVITY | P21: Top 5% most active in your ICP (LinkedIn) | R21: 0.96 | S21: 1.2 | T21: 2 | U21: Role and ICP align on title, industry, location, and company size. | V21: No | W21: 2026-09-07 09:24 | X21: NEW - not yet exported | Y21: 17429446
A22: Dan | B22: Cowling | C22: Agency Founder, President & CEO | D22: The Communications Group, Inc. | E22: 11 - 50 | F22: Advertising Services | G22: Little Rock, Arkansas, United States | H22: http://www.comgroup.com | I22: https://www.linkedin.com/in/dan-cowling-4a92a120 | J22: https://www.linkedin.com/company/the-communications-group-inc. | K22: Founder, President & CEO The Communications Group, Inc. | L22: 1987 - Present | O22: RECENT_ACTIVITY | P22: Top 5% most active in your ICP (LinkedIn) | R22: 0.96 | S22: 1.2 | T22: 2 | U22: Role maps to Founder/CEO and location and size fit the ICP. | V22: No | W22: 2026-09-07 09:24 | X22: NEW - not yet exported | Y22: 17429436
A23: Dominica | B23: Fehlau | C23: Client Success Manager | D23: TKX Media | E23: 11-50 | F23: Marketing Services | G23: St. Petersburg, Florida, United States | H23: https://nikaworldwide.wixsite.com/nika | I23: https://www.linkedin.com/in/dominica-fehlau | J23: https://www.linkedin.com/company/tkx-media | K23: Client Success Manager | Digital Marketing & Project Management — Campaign Strategy, Automation, CRM & AI | L23: December 2025 - Present | O23: RECENT_ACTIVITY | P23: Top 5% most active in your ICP (LinkedIn) | R23: 0.96 | S23: 1.2 | T23: 2 | U23: Role aligns with ICP; industry, location, and size match closely. | V23: No | W23: 2026-09-07 09:24 | X23: NEW - not yet exported | Y23: 17429391
A24: Caylin | B24: Sanders | C24: President, Founder & CEO | D24: EscapeMaker | E24: 1-10 employees | F24: Marketing Services | G24: Saugerties, New York, United States | H24: http://www.escapemaker.com | I24: https://www.linkedin.com/in/caylinsanders | J24: https://www.linkedin.com/company/escapemaker | K24: President, Founder and CEO at EscapeMaker.com | L24: September 2000 - Present | O24: RECENT_ACTIVITY | P24: Top 5% most active in your ICP (LinkedIn) | R24: 0.88 | S24: 1.2 | T24: 1.9 | U24: Executive founder/CEO match in US marketing services with near-ICP company size and location. | V24: No | W24: 2026-09-07 09:24 | X24: NEW - not yet exported | Y24: 17429390
A25: Matt | B25: Fantastic | C25: Creative Director | D25: Forever Stoked Creative | E25: 1-10 employees | F25: Design Services | G25: New Haven, Connecticut, United States | I25: https://www.linkedin.com/in/matt-fantastic | J25: https://www.linkedin.com/company/forever-stoked-creative | K25: Creative Director at Forever Stoked Creative | L25: 2007 - Present | O25: RECENT_ACTIVITY | P25: Top 5% most active in your ICP (LinkedIn) | R25: 0.82 | S25: 1.2 | T25: 1.8 | U25: Creative Director aligns with ICP title; Design Services in US; company size slightly smaller. | V25: No | W25: 2026-09-07 09:24 | X25: NEW - not yet exported | Y25: 17429387
A26: Christopher | B26: Carroll | C26: Art Director | D26: GradComm | E26: 11-50 | F26: Marketing Services | G26: United States | H26: https://www.krop.com/ccarr2222/ | I26: https://www.linkedin.com/in/christopher-james-carroll | J26: https://www.linkedin.com/company/gradcomm | K26: Design Professional & Creative Team Lead | L26: April 2024 - Present | O26: RECENT_ACTIVITY | P26: Top 5% most active in your ICP (LinkedIn) | R26: 1 | S26: 1.2 | T26: 2.1 | U26: Role, industry, size, and location align with the ICP. | V26: No | W26: 2026-09-07 09:24 | X26: NEW - not yet exported | Y26: 17429385
A27: Arlyn | B27: Hernandez | C27: Creative Director, Founder | D27: Biotonic Design | E27: 1-10 employees | F27: Design Services | G27: Miami, Florida, United States | H27: http://www.arlynhernandez.com | I27: https://www.linkedin.com/in/arlynhernandezmiami | J27: https://www.linkedin.com/company/biotonicdesign | K27: Creative Director at Biotonic, Founder at SAUSHI | L27: 2008 - Present | O27: RECENT_ACTIVITY | P27: Top 5% most active in your ICP (LinkedIn) | R27: 0.94 | S27: 1.2 | T27: 2 | U27: Strong fit: senior Creative Director/Founder at a US design services firm. | V27: No | W27: 2026-09-07 09:24 | X27: NEW - not yet exported | Y27: 17429341
A28: Jennifer | B28: Grinnell | C28: President/Creative Director | D28: BrandPlanet, LLC | E28: 1-10 employees | F28: Marketing Services | G28: Washington DC-Baltimore Area | H28: http://www.brandplanet.net | I28: https://www.linkedin.com/in/jennifer-grinnell-1940534 | J28: https://www.linkedin.com/company/brandplanet | K28: Creative Director I Brand Developer I Communications Strategist I Copywriter I Educator I Founder & President of Ellanor C. Lawrence Park Friends | L28: January 1999 - Present | O28: RECENT_ACTIVITY | P28: Top 5% most active in your ICP (LinkedIn) | R28: 0.84 | S28: 1.2 | T28: 1.9 | U28: Role and industry align with ICP; location in US and size near ICP but slightly smaller. | V28: No | W28: 2026-09-07 09:24 | X28: NEW - not yet exported | Y28: 17429337
A29: Holly | B29: Timmins | C29: Creative Director | D29: Creative Design Squared | E29: 1-10 employees | F29: Marketing Services | G29: Argyle, Texas, United States | H29: http://creativedesignsquared.com/ | I29: https://www.linkedin.com/in/holly-timmins-ab473250 | J29: https://www.linkedin.com/company/cdsquared | K29: Creative Director at Creative Design Squared | L29: November 2023 - Present | O29: RECENT_ACTIVITY | P29: Top 5% most active in your ICP (LinkedIn) | R29: 0.88 | S29: 1.2 | T29: 1.9 | U29: Role aligns with ICP; industry and location match US-based marketing services; company size is near ICP band. | V29: No | W29: 2026-09-07 09:24 | X29: NEW - not yet exported | Y29: 17429332
A30: Angelica | B30: Cifuentes Hernandez | C30: Founder - Creative Director | D30: Presentora designs | E30: 1-10 employees | F30: Marketing Services | G30: Chicago, Illinois, United States | H30: https://www.linkedin.com/redir/redirect?url=www.presentora.com&urlhash=V0Oa&trk=public_profile_topcard-website | I30: https://www.linkedin.com/in/angelicacifuentes | J30: https://www.linkedin.com/company/presentora-designs | K30: Breathing life into your presentations | Presentation Specialist & Creative Director | L30: February 2023 - Present | O30: RECENT_ACTIVITY | P30: Top 5% most active in your ICP (LinkedIn) | R30: 0.96 | S30: 1.2 | T30: 2 | U30: Founder/Creative Director in US marketing services aligns with ICP. | V30: No | W30: 2026-09-07 09:24 | X30: NEW - not yet exported | Y30: 17429329
A31: Niyati | B31: Kothary Shah | C31: Founder, Creative Director | D31: Create Forward | E31: 1-10 employees | F31: Design Services | G31: New York City Metropolitan Area | I31: https://www.linkedin.com/in/niyati-kothary-shah-a2103516 | J31: https://linkedin.com/company/92935001 | K31: Founder @ Create Forward | Bespoke design studio for CMOs + CGOs | Strategy, narrative & design for growth teams to secure funding, win clients & scale | Follow for more on strategic communication design | Ex-consulting | L31: 11/01/2008 - Present | O31: RECENT_ACTIVITY | P31: Top 5% most active in your ICP (LinkedIn) | R31: 0.9 | S31: 1.2 | T31: 2 | U31: Role aligns as Founder/Creative Director; industry Design Services; location US; company size near ICP. | V31: No | W31: 2026-09-07 09:24 | X31: NEW - not yet exported | Y31: 17429314
A32: Mike | B32: Conway | C32: Creative Director | D32: Jump Company | E32: 11-50 employees | F32: Marketing Services | G32: St Louis, Missouri, United States | H32: http://jumpcompany.com/ | I32: https://www.linkedin.com/in/mike-conway-a2095316 | J32: https://www.linkedin.com/company/jump-company | K32: Creative Director, Art Director, Graphic Designer for Advertising & Marketing | L32: April 2008 - Present | O32: RECENT_ACTIVITY | P32: Top 5% most active in your ICP (LinkedIn) | R32: 1 | S32: 1.2 | T32: 2.1 | U32: Profile aligns exactly with the ICP across title, industry, size, and location. | V32: No | W32: 2026-09-07 09:24 | X32: NEW - not yet exported | Y32: 17429313
A33: Lane | B33: Banning | C33: Founder, Creative Director | D33: UFO | E33: 1-10 employees | F33: Marketing Services | G33: New York, New York, United States | H33: www.lanebanning.com | I33: https://www.linkedin.com/in/lanebanning | J33: https://www.linkedin.com/company/ufoglobal | K33: label head & creative director | L33: June 2023 - Present | O33: RECENT_ACTIVITY | P33: Top 5% most active in your ICP (LinkedIn) | R33: 0.96 | S33: 1.2 | T33: 2 | U33: Founder title matches ICP, industry and location align, and company size is near ICP range. | V33: No | W33: 2026-09-07 09:24 | X33: NEW - not yet exported | Y33: 17429306
A34: Gabrielle | B34: Raumberger | C34: President, Creative Director | D34: EPOS Inc | E34: 1-10 employees | F34: Design Services | G34: Hermosa Beach, California, United States | H34: http://www.eposinc.com | I34: https://www.linkedin.com/in/gabrielle-raumberger-8975ab1 | J34: https://www.linkedin.com/company/epos-inc | K34: Creative Director, EPOS Inc., Brand Strategy and Design Studio | L34: 1990 - Present | O34: RECENT_ACTIVITY | P34: Top 5% most active in your ICP (LinkedIn) | R34: 0.84 | S34: 1.2 | T34: 1.9 | U34: Role and location strongly align; industry matches; company size is slightly off ICP bands. | V34: No | W34: 2026-09-07 09:24 | X34: NEW - not yet exported | Y34: 17429301
A35: Brandon | B35: Locke | C35: Founder, Art Director | D35: Studio Vermilion | E35: 1-10 employees | F35: Design Services | G35: Detroit Metropolitan Area | H35: https://www.Brandon-Locke.com | I35: https://www.linkedin.com/in/brandon-locke-35a14927 | J35: https://www.linkedin.com/company/studio-vermilion | K35: Freelance Creative, Art | Prev.  | Co-Director, Studio Vermilion | L35: November 2023 - Present | O35: RECENT_ACTIVITY | P35: Top 5% most active in your ICP (LinkedIn) | R35: 0.87 | S35: 1.2 | T35: 1.9 | U35: Founder in Design Services (US) with suitable company size; location match. | V35: No | W35: 2026-09-07 09:24 | X35: NEW - not yet exported | Y35: 17429296
A36: Aften | B36: Bell | C36: Founder & Creative Director | D36: Aften Design Studio | E36: 1-10 employees | F36: Design Services | G36: Dallas, Texas, United States | H36: http://www.aftenbell.com | I36: https://www.linkedin.com/in/aften-bell | J36: https://www.linkedin.com/company/aften-design-studio | K36: Founder & Creative Director at Aften Design Studio | Founder at The Love Pit Rescue | L36: January 2017 - Present | O36: RECENT_ACTIVITY | P36: Top 5% most active in your ICP (LinkedIn) | R36: 0.95 | S36: 1.2 | T36: 2 | U36: Role and industry align with the ICP; location matches; company size is close to ICP. | V36: No | W36: 2026-09-07 09:24 | X36: NEW - not yet exported | Y36: 17429281
A37: Nourhan | B37: Wahdan | C37: Founder & Creative Director | D37: pew. design bureau | E37: 2 - 10 | F37: Design Services | G37: Los Angeles Metropolitan Area | H37: Pewdesign.com | I37: https://www.linkedin.com/in/nourhanwahdan | J37: https://www.linkedin.com/company/pewdesignbureau | K37: Brand Strategist + Creative Director | Self-Proclaimed Toyfication Expert | Founder @ pew. design bureau | Top 3% LinkedIn Creator Worldwide | L37: September 2017 - Present | O37: RECENT_ACTIVITY | P37: Top 5% most active in your ICP (LinkedIn) | R37: 0.96 | S37: 1.2 | T37: 2 | U37: Role and company fit the ICP; industry, size, and US location align. | V37: No | W37: 2026-09-07 09:24 | X37: NEW - not yet exported | Y37: 17429276
A38: Syed Zuhair | B38: Zaidi | C38: Co-Founder & Creative Director | D38: ZHSync Digital | E38: 1-10 employees | F38: Marketing Services | G38: United States | I38: https://www.linkedin.com/in/zuhair-personal-branding | J38: https://www.linkedin.com/company/zhsync/ | K38: Co-Founder & Creative Director, ZHSync Digital | Brand systems + creative that grow profitable brands. | L38: 1/11/2024 - now | O38: RECENT_ACTIVITY | P38: Top 5% most active in your ICP (LinkedIn) | R38: 0.96 | S38: 1.2 | T38: 2 | U38: Role maps to Founder/Creative Director; industry and location align with the ICP; size is close to ICP bands. | V38: No | W38: 2026-09-07 09:24 | X38: NEW - not yet exported | Y38: 17429264
A39: Matt | B39: Yerman | C39: Creative Director, Founder | D39: Study Hall Studio | E39: 11-50 | F39: Design Services | G39: San Francisco Bay Area | H39: http://www.madeservice.net | I39: https://www.linkedin.com/in/matt-yerman-205a105b | J39: https://www.linkedin.com/company/studyhalldesign | K39: Co-Founder / Creative Director at Study Hall | L39: September 2020 - Present | O39: RECENT_ACTIVITY | P39: Top 5% most active in your ICP (LinkedIn) | R39: 1 | S39: 1.2 | T39: 2.1 | U39: Role, industry, location, and company size align with the ICP. | V39: No | W39: 2026-09-07 09:24 | X39: NEW - not yet exported | Y39: 17429259
A40: Mark | B40: Dreistadt | C40: President & CEO | D40: IDEX Pro | E40: 1-10 employees | F40: Marketing Services | G40: Export, Pennsylvania, United States | H40: http://www.infinityconcepts.com | I40: https://www.linkedin.com/in/markdreistadt | J40: https://www.linkedin.com/company/idex-pro | K40: Founder, President & CEO at Infinity Concepts and Inspire Media Group | L40: January 2024 - Present | O40: RECENT_ACTIVITY | P40: Top 5% most active in your ICP (LinkedIn) | R40: 0.9 | S40: 1.2 | T40: 2 | U40: Role aligns with ICP (Founder/CEO), industry and US location match; company size is slightly smaller than ICP. | V40: No | W40: 2026-09-07 09:24 | X40: NEW - not yet exported | Y40: 17429255
...

Sheet Summary
A1: Agency - Eikko leads — Gojiberry list 45132 (agent 'Agency - Eikko', id 29267)
A2: Source: Gojiberry API via Penji Gojiberry connector, pulled 2026-09-07 ~12:45 UTC (20:45 PHT). 'Previously exported' = LinkedIn URL matches one of the 2026-09-02 Dripify import files (Amanda Scott / Whitney Cole).
A4: Export status | B4: Leads
A5: NEW - not yet exported | B5: =COUNTIF(Leads!$X$2:$X$500,"NEW*") -> 238
A6: Previously exported (Amanda Scott, 2026-09-02) | B6: =COUNTIF(Leads!$X$2:$X$500,"Previously exported (Amanda Scott*") -> 131
A7: Previously exported (Whitney Cole, 2026-09-02) | B7: =COUNTIF(Leads!$X$2:$X$500,"Previously exported (Whitney Cole*") -> 130
A8: Total in list | B8: =SUM(B5:B7) -> 499
A10: Intent type (how Gojiberry found them) | B10: Leads | C10: Share
A11: RECENT_ACTIVITY | B11: =COUNTIF(Leads!$O$2:$O$500,A11) -> 192 | C11: =IF($B$8=0,0,B11/$B$8) -> 0.38476954
A12: LOOKALIKE | B12: =COUNTIF(Leads!$O$2:$O$500,A12) -> 163 | C12: =IF($B$8=0,0,B12/$B$8) -> 0.32665331
A13: RECENTLY_CHANGED_JOB | B13: =COUNTIF(Leads!$O$2:$O$500,A13) -> 53 | C13: =IF($B$8=0,0,B13/$B$8) -> 0.10621242
A14: SEARCH_KEYWORD | B14: =COUNTIF(Leads!$O$2:$O$500,A14) -> 48 | C14: =IF($B$8=0,0,B14/$B$8) -> 0.096192385
A15: INFLUENCER_PAGE_URL | B15: =COUNTIF(Leads!$O$2:$O$500,A15) -> 29 | C15: =IF($B$8=0,0,B15/$B$8) -> 0.058116232
A16: YOUR_PROFILE | B16: =COUNTIF(Leads!$O$2:$O$500,A16) -> 8 | C16: =IF($B$8=0,0,B16/$B$8) -> 0.016032064
A17: COMPETITOR_PAGE_URL | B17: =COUNTIF(Leads!$O$2:$O$500,A17) -> 6 | C17: =IF($B$8=0,0,B17/$B$8) -> 0.012024048
A18: Check: sum of intent types | B18: =SUM(B11:B17) -> 499
A20: Data quality | B20: Leads
A21: With email | B21: =COUNTIF(Leads!$M$2:$M$500,"?*") -> 0
A22: With phone | B22: =COUNTIF(Leads!$N$2:$N$500,"?*") -> 0
A23: Open to work | B23: =COUNTIF(Leads!$V$2:$V$500,"Yes") -> 0
A24: Total score ≥ 2.0 | B24: =COUNTIF(Leads!$T$2:$T$500,">=2") -> 261
A25: Average ICP fit score | B25: =IFERROR(AVERAGE(Leads!$R$2:$R$500),0) -> 0.90769539
A26: Added on 2026-09-07 (PHT) | B26: =COUNTIF(Leads!$W$2:$W$500,"2026-09-07*") -> 149
A27: Note: Gojiberry has enriched no emails or phones on this list (enrichment costs credits and was not run). Company-size labels vary because Gojiberry stores the raw LinkedIn value.
